<?xml version="1.0" encoding="UTF-8"?>
<testng-results skipped="0" failed="3" total="3" passed="0">
  <reporter-output>
  </reporter-output>
  <suite name="Suite" duration-ms="43249" started-at="2018-05-31T17:21:35Z" finished-at="2018-05-31T17:22:18Z">
    <groups>
    </groups>
    <test name="Test" duration-ms="43249" started-at="2018-05-31T17:21:35Z" finished-at="2018-05-31T17:22:18Z">
      <class name="TestNGProject.TestNG.TestNGClass">
        <test-method status="PASS" signature="startReport()[pri:0, instance:TestNGProject.TestNG.TestNGClass@724af044]" name="startReport" is-config="true" duration-ms="209" started-at="2018-05-31T22:51:35Z" finished-at="2018-05-31T22:51:35Z">
          <reporter-output>
          </reporter-output>
        </test-method> <!-- startReport -->
        <test-method status="PASS" signature="beforeMethod()[pri:0, instance:TestNGProject.TestNG.TestNGClass@724af044]" name="beforeMethod" is-config="true" duration-ms="10249" started-at="2018-05-31T22:51:35Z" finished-at="2018-05-31T22:51:46Z">
          <reporter-output>
          </reporter-output>
        </test-method> <!-- beforeMethod -->
        <test-method status="FAIL" signature="failTest()[pri:0, instance:TestNGProject.TestNG.TestNGClass@724af044]" name="failTest" duration-ms="21" started-at="2018-05-31T22:51:46Z" finished-at="2018-05-31T22:51:46Z">
          <exception class="java.lang.AssertionError">
            <message>
              <![CDATA[expected [true] but found [false]]]>
            </message>
            <full-stacktrace>
              <![CDATA[java.lang.AssertionError: expected [true] but found [false]
	at org.testng.Assert.fail(Assert.java:94)
	at org.testng.Assert.failNotEquals(Assert.java:494)
	at org.testng.Assert.assertTrue(Assert.java:42)
	at org.testng.Assert.assertTrue(Assert.java:52)
	at TestNGProject.TestNG.TestNGClass.failTest(TestNGClass.java:77)
	at sun.reflect.NativeMethodAccessorImpl.invoke0(Native Method)
	at sun.reflect.NativeMethodAccessorImpl.invoke(Unknown Source)
	at sun.reflect.DelegatingMethodAccessorImpl.invoke(Unknown Source)
	at java.lang.reflect.Method.invoke(Unknown Source)
	at org.testng.internal.MethodInvocationHelper.invokeMethod(MethodInvocationHelper.java:80)
	at org.testng.internal.Invoker.invokeMethod(Invoker.java:714)
	at org.testng.internal.Invoker.invokeTestMethod(Invoker.java:901)
	at org.testng.internal.Invoker.invokeTestMethods(Invoker.java:1231)
	at org.testng.internal.TestMethodWorker.invokeTestMethods(TestMethodWorker.java:127)
	at org.testng.internal.TestMethodWorker.run(TestMethodWorker.java:111)
	at org.testng.TestRunner.privateRun(TestRunner.java:767)
	at org.testng.TestRunner.run(TestRunner.java:617)
	at org.testng.SuiteRunner.runTest(SuiteRunner.java:334)
	at org.testng.SuiteRunner.runSequentially(SuiteRunner.java:329)
	at org.testng.SuiteRunner.privateRun(SuiteRunner.java:291)
	at org.testng.SuiteRunner.run(SuiteRunner.java:240)
	at org.testng.SuiteRunnerWorker.runSuite(SuiteRunnerWorker.java:52)
	at org.testng.SuiteRunnerWorker.run(SuiteRunnerWorker.java:86)
	at org.testng.TestNG.runSuitesSequentially(TestNG.java:1198)
	at org.testng.TestNG.runSuitesLocally(TestNG.java:1123)
	at org.testng.TestNG.run(TestNG.java:1031)
	at org.testng.remote.AbstractRemoteTestNG.run(AbstractRemoteTestNG.java:114)
	at org.testng.remote.RemoteTestNG.initAndRun(RemoteTestNG.java:251)
	at org.testng.remote.RemoteTestNG.main(RemoteTestNG.java:77)
]]>
            </full-stacktrace>
          </exception> <!-- java.lang.AssertionError -->
          <reporter-output>
          </reporter-output>
        </test-method> <!-- failTest -->
        <test-method status="PASS" signature="afterMethod(org.testng.ITestResult)[pri:0, instance:TestNGProject.TestNG.TestNGClass@724af044]" name="afterMethod" is-config="true" duration-ms="3135" started-at="2018-05-31T22:51:46Z" finished-at="2018-05-31T22:51:49Z">
          <params>
            <param index="0">
              <value>
                <![CDATA[[TestResult name=failTest status=FAILURE method=TestNGClass.failTest()[pri:0, instance:TestNGProject.TestNG.TestNGClass@724af044] output={null}]]]>
              </value>
            </param>
          </params>
          <reporter-output>
          </reporter-output>
        </test-method> <!-- afterMethod -->
        <test-method status="PASS" signature="beforeMethod()[pri:0, instance:TestNGProject.TestNG.TestNGClass@724af044]" name="beforeMethod" is-config="true" duration-ms="17190" started-at="2018-05-31T22:51:49Z" finished-at="2018-05-31T22:52:06Z">
          <reporter-output>
          </reporter-output>
        </test-method> <!-- beforeMethod -->
        <test-method status="FAIL" signature="failTest()[pri:0, instance:TestNGProject.TestNG.TestNGClass@724af044]" name="failTest" duration-ms="2" started-at="2018-05-31T22:52:06Z" finished-at="2018-05-31T22:52:06Z">
          <exception class="java.lang.AssertionError">
            <message>
              <![CDATA[expected [true] but found [false]]]>
            </message>
            <full-stacktrace>
              <![CDATA[java.lang.AssertionError: expected [true] but found [false]
	at org.testng.Assert.fail(Assert.java:94)
	at org.testng.Assert.failNotEquals(Assert.java:494)
	at org.testng.Assert.assertTrue(Assert.java:42)
	at org.testng.Assert.assertTrue(Assert.java:52)
	at TestNGProject.TestNG.TestNGClass.failTest(TestNGClass.java:77)
	at sun.reflect.NativeMethodAccessorImpl.invoke0(Native Method)
	at sun.reflect.NativeMethodAccessorImpl.invoke(Unknown Source)
	at sun.reflect.DelegatingMethodAccessorImpl.invoke(Unknown Source)
	at java.lang.reflect.Method.invoke(Unknown Source)
	at org.testng.internal.MethodInvocationHelper.invokeMethod(MethodInvocationHelper.java:80)
	at org.testng.internal.Invoker.invokeMethod(Invoker.java:714)
	at org.testng.internal.Invoker.retryFailed(Invoker.java:1049)
	at org.testng.internal.Invoker.invokeTestMethods(Invoker.java:1254)
	at org.testng.internal.TestMethodWorker.invokeTestMethods(TestMethodWorker.java:127)
	at org.testng.internal.TestMethodWorker.run(TestMethodWorker.java:111)
	at org.testng.TestRunner.privateRun(TestRunner.java:767)
	at org.testng.TestRunner.run(TestRunner.java:617)
	at org.testng.SuiteRunner.runTest(SuiteRunner.java:334)
	at org.testng.SuiteRunner.runSequentially(SuiteRunner.java:329)
	at org.testng.SuiteRunner.privateRun(SuiteRunner.java:291)
	at org.testng.SuiteRunner.run(SuiteRunner.java:240)
	at org.testng.SuiteRunnerWorker.runSuite(SuiteRunnerWorker.java:52)
	at org.testng.SuiteRunnerWorker.run(SuiteRunnerWorker.java:86)
	at org.testng.TestNG.runSuitesSequentially(TestNG.java:1198)
	at org.testng.TestNG.runSuitesLocally(TestNG.java:1123)
	at org.testng.TestNG.run(TestNG.java:1031)
	at org.testng.remote.AbstractRemoteTestNG.run(AbstractRemoteTestNG.java:114)
	at org.testng.remote.RemoteTestNG.initAndRun(RemoteTestNG.java:251)
	at org.testng.remote.RemoteTestNG.main(RemoteTestNG.java:77)
]]>
            </full-stacktrace>
          </exception> <!-- java.lang.AssertionError -->
          <reporter-output>
          </reporter-output>
        </test-method> <!-- failTest -->
        <test-method status="PASS" signature="afterMethod(org.testng.ITestResult)[pri:0, instance:TestNGProject.TestNG.TestNGClass@724af044]" name="afterMethod" is-config="true" duration-ms="1133" started-at="2018-05-31T22:52:06Z" finished-at="2018-05-31T22:52:07Z">
          <params>
            <param index="0">
              <value>
                <![CDATA[[TestResult name=failTest status=FAILURE method=TestNGClass.failTest()[pri:0, instance:TestNGProject.TestNG.TestNGClass@724af044] output={null}]]]>
              </value>
            </param>
          </params>
          <reporter-output>
          </reporter-output>
        </test-method> <!-- afterMethod -->
        <test-method status="PASS" signature="beforeMethod()[pri:0, instance:TestNGProject.TestNG.TestNGClass@724af044]" name="beforeMethod" is-config="true" duration-ms="10123" started-at="2018-05-31T22:52:07Z" finished-at="2018-05-31T22:52:17Z">
          <reporter-output>
          </reporter-output>
        </test-method> <!-- beforeMethod -->
        <test-method status="FAIL" signature="failTest()[pri:0, instance:TestNGProject.TestNG.TestNGClass@724af044]" name="failTest" duration-ms="2" started-at="2018-05-31T22:52:17Z" finished-at="2018-05-31T22:52:17Z">
          <exception class="java.lang.AssertionError">
            <message>
              <![CDATA[expected [true] but found [false]]]>
            </message>
            <full-stacktrace>
              <![CDATA[java.lang.AssertionError: expected [true] but found [false]
	at org.testng.Assert.fail(Assert.java:94)
	at org.testng.Assert.failNotEquals(Assert.java:494)
	at org.testng.Assert.assertTrue(Assert.java:42)
	at org.testng.Assert.assertTrue(Assert.java:52)
	at TestNGProject.TestNG.TestNGClass.failTest(TestNGClass.java:77)
	at sun.reflect.NativeMethodAccessorImpl.invoke0(Native Method)
	at sun.reflect.NativeMethodAccessorImpl.invoke(Unknown Source)
	at sun.reflect.DelegatingMethodAccessorImpl.invoke(Unknown Source)
	at java.lang.reflect.Method.invoke(Unknown Source)
	at org.testng.internal.MethodInvocationHelper.invokeMethod(MethodInvocationHelper.java:80)
	at org.testng.internal.Invoker.invokeMethod(Invoker.java:714)
	at org.testng.internal.Invoker.retryFailed(Invoker.java:1049)
	at org.testng.internal.Invoker.invokeTestMethods(Invoker.java:1254)
	at org.testng.internal.TestMethodWorker.invokeTestMethods(TestMethodWorker.java:127)
	at org.testng.internal.TestMethodWorker.run(TestMethodWorker.java:111)
	at org.testng.TestRunner.privateRun(TestRunner.java:767)
	at org.testng.TestRunner.run(TestRunner.java:617)
	at org.testng.SuiteRunner.runTest(SuiteRunner.java:334)
	at org.testng.SuiteRunner.runSequentially(SuiteRunner.java:329)
	at org.testng.SuiteRunner.privateRun(SuiteRunner.java:291)
	at org.testng.SuiteRunner.run(SuiteRunner.java:240)
	at org.testng.SuiteRunnerWorker.runSuite(SuiteRunnerWorker.java:52)
	at org.testng.SuiteRunnerWorker.run(SuiteRunnerWorker.java:86)
	at org.testng.TestNG.runSuitesSequentially(TestNG.java:1198)
	at org.testng.TestNG.runSuitesLocally(TestNG.java:1123)
	at org.testng.TestNG.run(TestNG.java:1031)
	at org.testng.remote.AbstractRemoteTestNG.run(AbstractRemoteTestNG.java:114)
	at org.testng.remote.RemoteTestNG.initAndRun(RemoteTestNG.java:251)
	at org.testng.remote.RemoteTestNG.main(RemoteTestNG.java:77)
]]>
            </full-stacktrace>
          </exception> <!-- java.lang.AssertionError -->
          <reporter-output>
          </reporter-output>
        </test-method> <!-- failTest -->
        <test-method status="PASS" signature="afterMethod(org.testng.ITestResult)[pri:0, instance:TestNGProject.TestNG.TestNGClass@724af044]" name="afterMethod" is-config="true" duration-ms="1154" started-at="2018-05-31T22:52:17Z" finished-at="2018-05-31T22:52:18Z">
          <params>
            <param index="0">
              <value>
                <![CDATA[[TestResult name=failTest status=FAILURE method=TestNGClass.failTest()[pri:0, instance:TestNGProject.TestNG.TestNGClass@724af044] output={null}]]]>
              </value>
            </param>
          </params>
          <reporter-output>
          </reporter-output>
        </test-method> <!-- afterMethod -->
      </class> <!-- TestNGProject.TestNG.TestNGClass -->
    </test> <!-- Test -->
  </suite> <!-- Suite -->
</testng-results>
